[2023-10-21T11:07:24.206+0000] {logging_mixin.py:151} INFO - Changing /opt/***/logs/dag_id=random_cannabis_save/run_id=scheduled__2023-10-20T12:00:00+00:00/task_id=get_random_cannabis permission to 509
[2023-10-21T11:07:24.253+0000] {logging_mixin.py:151} INFO - Changing /opt/***/logs/dag_id=random_cannabis_save/run_id=scheduled__2023-10-20T12:00:00+00:00/task_id=get_random_cannabis permission to 509
[2023-10-21T11:07:24.323+0000] {taskinstance.py:1159} INFO - Dependencies all met for dep_context=non-requeueable deps ti=<TaskInstance: random_cannabis_save.get_random_cannabis scheduled__2023-10-20T12:00:00+00:00 [queued]>
[2023-10-21T11:07:24.335+0000] {taskinstance.py:1159} INFO - Dependencies all met for dep_context=requeueable deps ti=<TaskInstance: random_cannabis_save.get_random_cannabis scheduled__2023-10-20T12:00:00+00:00 [queued]>
[2023-10-21T11:07:24.336+0000] {taskinstance.py:1361} INFO - Starting attempt 1 of 1
[2023-10-21T11:07:24.357+0000] {taskinstance.py:1382} INFO - Executing <Task(RandomCannabisOperator): get_random_cannabis> on 2023-10-20 12:00:00+00:00
[2023-10-21T11:07:24.364+0000] {standard_task_runner.py:57} INFO - Started process 97 to run task
[2023-10-21T11:07:24.368+0000] {standard_task_runner.py:84} INFO - Running: ['***', 'tasks', 'run', 'random_cannabis_save', 'get_random_cannabis', 'scheduled__2023-10-20T12:00:00+00:00', '--job-id', '2', '--raw', '--subdir', 'DAGS_FOLDER/random_cannabis_save.py', '--cfg-path', '/tmp/tmpf62gzz6f']
[2023-10-21T11:07:24.369+0000] {standard_task_runner.py:85} INFO - Job 2: Subtask get_random_cannabis
[2023-10-21T11:07:24.387+0000] {warnings.py:109} WARNING - /home/***/.local/lib/python3.10/site-packages/***/settings.py:193: DeprecationWarning: The sql_alchemy_conn option in [core] has been moved to the sql_alchemy_conn option in [database] - the old setting has been used, but please update your config.
  SQL_ALCHEMY_CONN = conf.get("database", "SQL_ALCHEMY_CONN")

[2023-10-21T11:07:24.438+0000] {logging_mixin.py:151} INFO - Changing /opt/***/logs/dag_id=random_cannabis_save/run_id=scheduled__2023-10-20T12:00:00+00:00/task_id=get_random_cannabis permission to 509
[2023-10-21T11:07:24.442+0000] {task_command.py:416} INFO - Running <TaskInstance: random_cannabis_save.get_random_cannabis scheduled__2023-10-20T12:00:00+00:00 [running]> on host 1646a4c502fb
[2023-10-21T11:07:24.535+0000] {taskinstance.py:1662} INFO - Exporting env vars: AIRFLOW_CTX_DAG_OWNER='babintseva' AIRFLOW_CTX_DAG_ID='random_cannabis_save' AIRFLOW_CTX_TASK_ID='get_random_cannabis' AIRFLOW_CTX_EXECUTION_DATE='2023-10-20T12:00:00+00:00' AIRFLOW_CTX_TRY_NUMBER='1' AIRFLOW_CTX_DAG_RUN_ID='scheduled__2023-10-20T12:00:00+00:00'
[2023-10-21T11:07:25.946+0000] {taskinstance.py:1937} ERROR - Task failed with exception
Traceback (most recent call last):
  File "/opt/airflow/plugins/random_cannabis_operator.py", line 43, in execute
    self.save_data(data)
  File "/opt/airflow/plugins/random_cannabis_operator.py", line 19, in save_data
    print(pg_hook.get_url())
AttributeError: 'PostgresHook' object has no attribute 'get_url'. Did you mean: 'get_uri'?
[2023-10-21T11:07:25.978+0000] {taskinstance.py:1400} INFO - Marking task as FAILED. dag_id=random_cannabis_save, task_id=get_random_cannabis, execution_date=20231020T120000, start_date=20231021T110724, end_date=20231021T110725
[2023-10-21T11:07:25.995+0000] {standard_task_runner.py:104} ERROR - Failed to execute job 2 for task get_random_cannabis ('PostgresHook' object has no attribute 'get_url'; 97)
[2023-10-21T11:07:26.027+0000] {local_task_job_runner.py:228} INFO - Task exited with return code 1
[2023-10-21T11:07:26.058+0000] {taskinstance.py:2778} INFO - 0 downstream tasks scheduled from follow-on schedule check
[2023-10-21T11:17:41.316+0000] {logging_mixin.py:151} INFO - Changing /opt/***/logs/dag_id=random_cannabis_save/run_id=scheduled__2023-10-20T12:00:00+00:00/task_id=get_random_cannabis permission to 509
[2023-10-21T11:17:41.360+0000] {logging_mixin.py:151} INFO - Changing /opt/***/logs/dag_id=random_cannabis_save/run_id=scheduled__2023-10-20T12:00:00+00:00/task_id=get_random_cannabis permission to 509
[2023-10-21T11:17:41.404+0000] {taskinstance.py:1159} INFO - Dependencies all met for dep_context=non-requeueable deps ti=<TaskInstance: random_cannabis_save.get_random_cannabis scheduled__2023-10-20T12:00:00+00:00 [queued]>
[2023-10-21T11:17:41.415+0000] {taskinstance.py:1159} INFO - Dependencies all met for dep_context=requeueable deps ti=<TaskInstance: random_cannabis_save.get_random_cannabis scheduled__2023-10-20T12:00:00+00:00 [queued]>
[2023-10-21T11:17:41.417+0000] {taskinstance.py:1361} INFO - Starting attempt 1 of 1
[2023-10-21T11:17:41.438+0000] {taskinstance.py:1382} INFO - Executing <Task(RandomCannabisOperator): get_random_cannabis> on 2023-10-20 12:00:00+00:00
[2023-10-21T11:17:41.447+0000] {standard_task_runner.py:57} INFO - Started process 251 to run task
[2023-10-21T11:17:41.451+0000] {standard_task_runner.py:84} INFO - Running: ['***', 'tasks', 'run', 'random_cannabis_save', 'get_random_cannabis', 'scheduled__2023-10-20T12:00:00+00:00', '--job-id', '7', '--raw', '--subdir', 'DAGS_FOLDER/random_cannabis_save.py', '--cfg-path', '/tmp/tmpw6nll86q']
[2023-10-21T11:17:41.453+0000] {standard_task_runner.py:85} INFO - Job 7: Subtask get_random_cannabis
[2023-10-21T11:17:41.471+0000] {warnings.py:109} WARNING - /home/***/.local/lib/python3.10/site-packages/***/settings.py:193: DeprecationWarning: The sql_alchemy_conn option in [core] has been moved to the sql_alchemy_conn option in [database] - the old setting has been used, but please update your config.
  SQL_ALCHEMY_CONN = conf.get("database", "SQL_ALCHEMY_CONN")

[2023-10-21T11:17:41.519+0000] {logging_mixin.py:151} INFO - Changing /opt/***/logs/dag_id=random_cannabis_save/run_id=scheduled__2023-10-20T12:00:00+00:00/task_id=get_random_cannabis permission to 509
[2023-10-21T11:17:41.523+0000] {task_command.py:416} INFO - Running <TaskInstance: random_cannabis_save.get_random_cannabis scheduled__2023-10-20T12:00:00+00:00 [running]> on host 1058d8ad5e78
[2023-10-21T11:17:41.625+0000] {taskinstance.py:1662} INFO - Exporting env vars: AIRFLOW_CTX_DAG_OWNER='babintseva' AIRFLOW_CTX_DAG_ID='random_cannabis_save' AIRFLOW_CTX_TASK_ID='get_random_cannabis' AIRFLOW_CTX_EXECUTION_DATE='2023-10-20T12:00:00+00:00' AIRFLOW_CTX_TRY_NUMBER='1' AIRFLOW_CTX_DAG_RUN_ID='scheduled__2023-10-20T12:00:00+00:00'
[2023-10-21T11:17:42.533+0000] {base.py:73} INFO - Using connection ID 'conn_pg' for task execution.
[2023-10-21T11:17:42.534+0000] {logging_mixin.py:151} INFO - postgresql://***:***@192.168.1.113:5434/***?__extra__=%7B%7D
[2023-10-21T11:17:42.543+0000] {base.py:73} INFO - Using connection ID 'conn_pg' for task execution.
[2023-10-21T11:17:42.546+0000] {taskinstance.py:1937} ERROR - Task failed with exception
Traceback (most recent call last):
  File "/home/airflow/.local/lib/python3.10/site-packages/sqlalchemy/engine/base.py", line 3371, in _wrap_pool_connect
    return fn()
  File "/home/airflow/.local/lib/python3.10/site-packages/sqlalchemy/pool/base.py", line 327, in connect
    return _ConnectionFairy._checkout(self)
  File "/home/airflow/.local/lib/python3.10/site-packages/sqlalchemy/pool/base.py", line 894, in _checkout
    fairy = _ConnectionRecord.checkout(pool)
  File "/home/airflow/.local/lib/python3.10/site-packages/sqlalchemy/pool/base.py", line 493, in checkout
    rec = pool._do_get()
  File "/home/airflow/.local/lib/python3.10/site-packages/sqlalchemy/pool/impl.py", line 145, in _do_get
    with util.safe_reraise():
  File "/home/airflow/.local/lib/python3.10/site-packages/sqlalchemy/util/langhelpers.py", line 70, in __exit__
    compat.raise_(
  File "/home/airflow/.local/lib/python3.10/site-packages/sqlalchemy/util/compat.py", line 211, in raise_
    raise exception
  File "/home/airflow/.local/lib/python3.10/site-packages/sqlalchemy/pool/impl.py", line 143, in _do_get
    return self._create_connection()
  File "/home/airflow/.local/lib/python3.10/site-packages/sqlalchemy/pool/base.py", line 273, in _create_connection
    return _ConnectionRecord(self)
  File "/home/airflow/.local/lib/python3.10/site-packages/sqlalchemy/pool/base.py", line 388, in __init__
    self.__connect()
  File "/home/airflow/.local/lib/python3.10/site-packages/sqlalchemy/pool/base.py", line 690, in __connect
    with util.safe_reraise():
  File "/home/airflow/.local/lib/python3.10/site-packages/sqlalchemy/util/langhelpers.py", line 70, in __exit__
    compat.raise_(
  File "/home/airflow/.local/lib/python3.10/site-packages/sqlalchemy/util/compat.py", line 211, in raise_
    raise exception
  File "/home/airflow/.local/lib/python3.10/site-packages/sqlalchemy/pool/base.py", line 686, in __connect
    self.dbapi_connection = connection = pool._invoke_creator(self)
  File "/home/airflow/.local/lib/python3.10/site-packages/sqlalchemy/engine/create.py", line 574, in connect
    return dialect.connect(*cargs, **cparams)
  File "/home/airflow/.local/lib/python3.10/site-packages/sqlalchemy/engine/default.py", line 598, in connect
    return self.dbapi.connect(*cargs, **cparams)
  File "/home/airflow/.local/lib/python3.10/site-packages/psycopg2/__init__.py", line 121, in connect
    dsn = _ext.make_dsn(dsn, **kwargs)
  File "/home/airflow/.local/lib/python3.10/site-packages/psycopg2/extensions.py", line 167, in make_dsn
    parse_dsn(dsn)
psycopg2.ProgrammingError: invalid dsn: invalid connection option "__extra__"


The above exception was the direct cause of the following exception:

Traceback (most recent call last):
  File "/opt/airflow/plugins/random_cannabis_operator.py", line 43, in execute
    self.save_data(data)
  File "/opt/airflow/plugins/random_cannabis_operator.py", line 21, in save_data
    db.begin()
  File "/home/airflow/.local/lib/python3.10/site-packages/dataset/database.py", line 121, in begin
    self.local.tx.append(self.executable.begin())
  File "/home/airflow/.local/lib/python3.10/site-packages/dataset/database.py", line 83, in executable
    self.connections[tid] = self.engine.connect()
  File "/home/airflow/.local/lib/python3.10/site-packages/sqlalchemy/engine/base.py", line 3325, in connect
    return self._connection_cls(self, close_with_result=close_with_result)
  File "/home/airflow/.local/lib/python3.10/site-packages/sqlalchemy/engine/base.py", line 96, in __init__
    else engine.raw_connection()
  File "/home/airflow/.local/lib/python3.10/site-packages/sqlalchemy/engine/base.py", line 3404, in raw_connection
    return self._wrap_pool_connect(self.pool.connect, _connection)
  File "/home/airflow/.local/lib/python3.10/site-packages/sqlalchemy/engine/base.py", line 3374, in _wrap_pool_connect
    Connection._handle_dbapi_exception_noconnection(
  File "/home/airflow/.local/lib/python3.10/site-packages/sqlalchemy/engine/base.py", line 2208, in _handle_dbapi_exception_noconnection
    util.raise_(
  File "/home/airflow/.local/lib/python3.10/site-packages/sqlalchemy/util/compat.py", line 211, in raise_
    raise exception
  File "/home/airflow/.local/lib/python3.10/site-packages/sqlalchemy/engine/base.py", line 3371, in _wrap_pool_connect
    return fn()
  File "/home/airflow/.local/lib/python3.10/site-packages/sqlalchemy/pool/base.py", line 327, in connect
    return _ConnectionFairy._checkout(self)
  File "/home/airflow/.local/lib/python3.10/site-packages/sqlalchemy/pool/base.py", line 894, in _checkout
    fairy = _ConnectionRecord.checkout(pool)
  File "/home/airflow/.local/lib/python3.10/site-packages/sqlalchemy/pool/base.py", line 493, in checkout
    rec = pool._do_get()
  File "/home/airflow/.local/lib/python3.10/site-packages/sqlalchemy/pool/impl.py", line 145, in _do_get
    with util.safe_reraise():
  File "/home/airflow/.local/lib/python3.10/site-packages/sqlalchemy/util/langhelpers.py", line 70, in __exit__
    compat.raise_(
  File "/home/airflow/.local/lib/python3.10/site-packages/sqlalchemy/util/compat.py", line 211, in raise_
    raise exception
  File "/home/airflow/.local/lib/python3.10/site-packages/sqlalchemy/pool/impl.py", line 143, in _do_get
    return self._create_connection()
  File "/home/airflow/.local/lib/python3.10/site-packages/sqlalchemy/pool/base.py", line 273, in _create_connection
    return _ConnectionRecord(self)
  File "/home/airflow/.local/lib/python3.10/site-packages/sqlalchemy/pool/base.py", line 388, in __init__
    self.__connect()
  File "/home/airflow/.local/lib/python3.10/site-packages/sqlalchemy/pool/base.py", line 690, in __connect
    with util.safe_reraise():
  File "/home/airflow/.local/lib/python3.10/site-packages/sqlalchemy/util/langhelpers.py", line 70, in __exit__
    compat.raise_(
  File "/home/airflow/.local/lib/python3.10/site-packages/sqlalchemy/util/compat.py", line 211, in raise_
    raise exception
  File "/home/airflow/.local/lib/python3.10/site-packages/sqlalchemy/pool/base.py", line 686, in __connect
    self.dbapi_connection = connection = pool._invoke_creator(self)
  File "/home/airflow/.local/lib/python3.10/site-packages/sqlalchemy/engine/create.py", line 574, in connect
    return dialect.connect(*cargs, **cparams)
  File "/home/airflow/.local/lib/python3.10/site-packages/sqlalchemy/engine/default.py", line 598, in connect
    return self.dbapi.connect(*cargs, **cparams)
  File "/home/airflow/.local/lib/python3.10/site-packages/psycopg2/__init__.py", line 121, in connect
    dsn = _ext.make_dsn(dsn, **kwargs)
  File "/home/airflow/.local/lib/python3.10/site-packages/psycopg2/extensions.py", line 167, in make_dsn
    parse_dsn(dsn)
sqlalchemy.exc.ProgrammingError: (psycopg2.ProgrammingError) invalid dsn: invalid connection option "__extra__"

(Background on this error at: https://sqlalche.me/e/14/f405)
[2023-10-21T11:17:42.562+0000] {taskinstance.py:1400} INFO - Marking task as FAILED. dag_id=random_cannabis_save, task_id=get_random_cannabis, execution_date=20231020T120000, start_date=20231021T111741, end_date=20231021T111742
[2023-10-21T11:17:42.583+0000] {standard_task_runner.py:104} ERROR - Failed to execute job 7 for task get_random_cannabis ((psycopg2.ProgrammingError) invalid dsn: invalid connection option "__extra__"

(Background on this error at: https://sqlalche.me/e/14/f405); 251)
[2023-10-21T11:17:42.631+0000] {local_task_job_runner.py:228} INFO - Task exited with return code 1
[2023-10-21T11:17:42.664+0000] {taskinstance.py:2778} INFO - 0 downstream tasks scheduled from follow-on schedule check
[2023-10-21T11:54:16.412+0000] {logging_mixin.py:151} INFO - Changing /opt/***/logs/dag_id=random_cannabis_save/run_id=scheduled__2023-10-20T12:00:00+00:00/task_id=get_random_cannabis permission to 509
[2023-10-21T11:54:16.454+0000] {logging_mixin.py:151} INFO - Changing /opt/***/logs/dag_id=random_cannabis_save/run_id=scheduled__2023-10-20T12:00:00+00:00/task_id=get_random_cannabis permission to 509
[2023-10-21T11:54:16.495+0000] {taskinstance.py:1159} INFO - Dependencies all met for dep_context=non-requeueable deps ti=<TaskInstance: random_cannabis_save.get_random_cannabis scheduled__2023-10-20T12:00:00+00:00 [queued]>
[2023-10-21T11:54:16.505+0000] {taskinstance.py:1159} INFO - Dependencies all met for dep_context=requeueable deps ti=<TaskInstance: random_cannabis_save.get_random_cannabis scheduled__2023-10-20T12:00:00+00:00 [queued]>
[2023-10-21T11:54:16.506+0000] {taskinstance.py:1361} INFO - Starting attempt 1 of 1
[2023-10-21T11:54:16.523+0000] {taskinstance.py:1382} INFO - Executing <Task(RandomCannabisOperator): get_random_cannabis> on 2023-10-20 12:00:00+00:00
[2023-10-21T11:54:16.532+0000] {standard_task_runner.py:57} INFO - Started process 83 to run task
[2023-10-21T11:54:16.536+0000] {standard_task_runner.py:84} INFO - Running: ['***', 'tasks', 'run', 'random_cannabis_save', 'get_random_cannabis', 'scheduled__2023-10-20T12:00:00+00:00', '--job-id', '9', '--raw', '--subdir', 'DAGS_FOLDER/random_cannabis_save.py', '--cfg-path', '/tmp/tmp2frqre6f']
[2023-10-21T11:54:16.538+0000] {standard_task_runner.py:85} INFO - Job 9: Subtask get_random_cannabis
[2023-10-21T11:54:16.556+0000] {warnings.py:109} WARNING - /home/***/.local/lib/python3.10/site-packages/***/settings.py:193: DeprecationWarning: The sql_alchemy_conn option in [core] has been moved to the sql_alchemy_conn option in [database] - the old setting has been used, but please update your config.
  SQL_ALCHEMY_CONN = conf.get("database", "SQL_ALCHEMY_CONN")

[2023-10-21T11:54:16.600+0000] {logging_mixin.py:151} INFO - Changing /opt/***/logs/dag_id=random_cannabis_save/run_id=scheduled__2023-10-20T12:00:00+00:00/task_id=get_random_cannabis permission to 509
[2023-10-21T11:54:16.604+0000] {task_command.py:416} INFO - Running <TaskInstance: random_cannabis_save.get_random_cannabis scheduled__2023-10-20T12:00:00+00:00 [running]> on host 47ce066e5721
[2023-10-21T11:54:16.699+0000] {taskinstance.py:1662} INFO - Exporting env vars: AIRFLOW_CTX_DAG_OWNER='babintseva' AIRFLOW_CTX_DAG_ID='random_cannabis_save' AIRFLOW_CTX_TASK_ID='get_random_cannabis' AIRFLOW_CTX_EXECUTION_DATE='2023-10-20T12:00:00+00:00' AIRFLOW_CTX_TRY_NUMBER='1' AIRFLOW_CTX_DAG_RUN_ID='scheduled__2023-10-20T12:00:00+00:00'
[2023-10-21T11:54:17.539+0000] {base.py:73} INFO - Using connection ID 'conn_pg' for task execution.
[2023-10-21T11:54:17.540+0000] {logging_mixin.py:151} INFO - postgresql://***:***@192.168.1.113:5434/***?__extra__=%7B%7D
[2023-10-21T11:54:17.583+0000] {taskinstance.py:1937} ERROR - Task failed with exception
Traceback (most recent call last):
  File "/opt/airflow/plugins/random_cannabis_operator.py", line 43, in execute
    self.save_data(data)
  File "/opt/airflow/plugins/random_cannabis_operator.py", line 20, in save_data
    db = dataset.connect('postgres://postgres:postgres@192.168.1.113:5432/db_homework')
  File "/home/airflow/.local/lib/python3.10/site-packages/dataset/__init__.py", line 48, in connect
    return Database(
  File "/home/airflow/.local/lib/python3.10/site-packages/dataset/database.py", line 57, in __init__
    self.engine = create_engine(url, **engine_kwargs)
  File "<string>", line 2, in create_engine
  File "/home/airflow/.local/lib/python3.10/site-packages/sqlalchemy/util/deprecations.py", line 375, in warned
    return fn(*args, **kwargs)
  File "/home/airflow/.local/lib/python3.10/site-packages/sqlalchemy/engine/create.py", line 518, in create_engine
    entrypoint = u._get_entrypoint()
  File "/home/airflow/.local/lib/python3.10/site-packages/sqlalchemy/engine/url.py", line 662, in _get_entrypoint
    cls = registry.load(name)
  File "/home/airflow/.local/lib/python3.10/site-packages/sqlalchemy/util/langhelpers.py", line 343, in load
    raise exc.NoSuchModuleError(
sqlalchemy.exc.NoSuchModuleError: Can't load plugin: sqlalchemy.dialects:postgres
[2023-10-21T11:54:17.599+0000] {taskinstance.py:1400} INFO - Marking task as FAILED. dag_id=random_cannabis_save, task_id=get_random_cannabis, execution_date=20231020T120000, start_date=20231021T115416, end_date=20231021T115417
[2023-10-21T11:54:17.623+0000] {standard_task_runner.py:104} ERROR - Failed to execute job 9 for task get_random_cannabis (Can't load plugin: sqlalchemy.dialects:postgres; 83)
[2023-10-21T11:54:17.673+0000] {local_task_job_runner.py:228} INFO - Task exited with return code 1
[2023-10-21T11:54:17.722+0000] {taskinstance.py:2778} INFO - 0 downstream tasks scheduled from follow-on schedule check
